Workbook

Sheet 花名册
A1: 员工姓名 | B1: 员工编号 | C1: 员工姓名 | D1: 部门 | E1: 性别 | F1: 考勤班次 | G1: 岗位 | H1: 班组 | I1: 入职日期 | J1: 离职时间 | K1: 移动电话 | L1: 来源于s-HR | M1: HR员工 | N1: 费用归属 | O1: 入住时间
A2: 李信伟 | B2: JG002723 | C2: 李信伟 | F2: 默认 | G2: A班包装工 | H2: 默认 | I2: 2025-05-13 | K2: 15011864749 | L2: 是 | M2: 否
A3: 潘怀星 | B3: JG002722 | C3: 潘怀星 | F3: 默认 | G3: A班包装工 | H3: 默认 | I3: 2025-05-13 | K3: 15977828938 | L3: 是 | M3: 否
A4: 舒新 | B4: JG002706 | C4: 舒新 | F4: 默认 | G4: B班包装工 | H4: 默认 | I4: 2025-05-06 | K4: 13536601096 | L4: 是 | M4: 否
A5: 蔡金星 | B5: JG003233 | C5: 蔡金星 | F5: 默认 | G5: 厨师 | H5: 默认 | I5: 2026-06-25 | L5: 是 | M5: 否 | N5: 管理费用-福利费
A6: 蔡源琪 | B6: JG002615 | C6: 蔡源琪 | F6: 默认 | G6: 证券事务代表 | H6: 默认 | I6: 2025-03-24 | K6: 18824625725 | L6: 是 | M6: 否 | N6: 管理费用
A7: 岑盛大 | B7: JG000170 | C7: 岑盛大 | D7: 人资行政部 | E7: 男 | F7: 默认 | G7: 主厨 | H7: 默认 | I7: 2020-05-18 | K7: 13202645700 | L7: 是 | M7: 否 | N7: 管理费用-福利费 | O7: 43969
A8: 曾红全 | B8: JG000066 | C8: 曾红全 | D8: 人资行政部 | E8: 男 | F8: 默认 | G8: 保安 | H8: 默认 | I8: 2016-04-23 | K8: 18823097450 | L8: 是 | M8: 否 | N8: 管理费用 | O8: 42483
A9: 曾梓毅 | B9: JG000594 | C9: 曾梓毅 | D9: 生产部 | E9: 男 | F9: 默认 | G9: 采购员 | H9: 默认 | I9: 2024-09-03 | K9: 13178538194 | L9: 是 | M9: 否 | N9: 管理费用 | O9: 44578
A10: 陈建成 | B10: JG000053 | C10: 陈建成 | D10: 人资行政部 | E10: 男 | F10: 默认 | G10: 保安 | H10: 默认 | I10: 2015-06-27 | K10: 13726660756 | L10: 是 | M10: 否 | N10: 管理费用 | O10: 42182
A11: 陈伦香 | B11: JG002597 | C11: 陈伦香 | D11: 人资行政部 | E11: 女 | F11: 默认 | G11: 厨工 | H11: 默认 | I11: 2025-03-05 | K11: 13416472193 | L11: 是 | M11: 否 | N11: 管理费用-福利费 | O11: 45731
A12: 陈望海 | B12: JG000059 | C12: 陈望海 | D12: 人资行政部 | E12: 男 | F12: 默认 | G12: 保安 | H12: 默认 | I12: 2016-01-13 | K12: 13415570501 | L12: 是 | M12: 否 | N12: 管理费用 | O12: 42382
A13: 陈苑平 | B13: JG000072 | C13: 陈苑平 | F13: 默认 | G13: 财务经理 | H13: 默认 | I13: 2016-12-27 | K13: 13536600218 | L13: 是 | M13: 否 | N13: 管理费用
A14: 陈泽光 | B14: JG001487 | C14: 陈泽光 | F14: 默认 | G14: 总监 | H14: 默认 | I14: 2023-03-01 | K14: 13590373105 | L14: 是 | M14: 否 | N14: 管理费用
A15: 陈周红 | B15: JG000125 | C15: 陈周红 | F15: 默认 | G15: 后勤杂工 | H15: 默认 | I15: 2018-04-17 | K15: 13703065740 | L15: 是 | M15: 否 | N15: 管理费用
A16: 池燕婷 | B16: JG001538 | C16: 池燕婷 | F16: 默认 | G16: 行政文员 | H16: 默认 | I16: 2023-08-01 | K16: 13612528257 | L16: 是 | M16: 否 | N16: 管理费用
A17: 邓利 | B17: JG000488 | C17: 邓利 | F17: 默认 | G17: 采购专员 | H17: 默认 | I17: 2025-04-01 | K17: 13724929801 | L17: 是 | M17: 否 | N17: 管理费用
A18: 邓艳青 | B18: JG001545 | C18: 邓艳青 | F18: 默认 | G18: 后勤助理 | H18: 默认 | I18: 2018-07-24 | K18: 13640179631 | L18: 是 | M18: 否 | N18: 管理费用
A19: 杜国基 | B19: JG000716 | C19: 杜国基 | F19: 默认 | G19: 中转仓司机 | H19: 默认 | I19: 2022-02-17 | K19: 13450552327 | L19: 是 | M19: 否 | N19: 管理费用
A20: 甘作敬 | B20: JG000020 | C20: 甘作敬 | D20: 人资行政部 | E20: 男 | F20: 默认 | G20: 司机 | H20: 默认 | I20: 2015-01-01 | K20: 13690168890 | L20: 是 | M20: 否 | N20: 管理费用 | O20: 39513
A21: 高妹妃 | B21: JG000019 | C21: 高妹妃 | F21: 默认 | G21: 薪酬绩效主管 | H21: 默认 | I21: 2024-07-01 | K21: 18675135279 | L21: 是 | M21: 否 | N21: 管理费用
A22: 黄超亮 | B22: JG000001 | C22: 黄超亮 | F22: 默认 | G22: 总经理 | H22: 默认 | I22: 2001-11-01 | K22: 13703063007 | L22: 是 | M22: 否 | N22: 管理费用
A23: 黄嘉杰 | B23: JG000055 | C23: 黄嘉杰 | D23: 采购部 | E23: 男 | F23: 默认 | G23: 采购主管 | H23: 默认 | I23: 2016-02-16 | K23: 13450573814 | L23: 是 | M23: 否 | N23: 管理费用 | O23: 42416
A24: 黄林烽 | B24: JG002610 | C24: 黄林烽 | F24: 默认 | H24: 默认 | K24: 18027781202 | L24: 是 | M24: 否 | N24: 管理费用
A25: 黄艳 | B25: JG000006 | C25: 黄艳 | F25: 默认 | G25: 总账会计 | H25: 默认 | I25: 2013-08-06 | K25: 13420829362 | L25: 是 | M25: 否 | N25: 管理费用
A26: 黄莹 | B26: JG003169 | C26: 黄莹 | D26: 人资行政部 | E26: 女 | F26: 默认 | G26: 人事文员 | H26: 默认 | I26: 2026-07-01 | L26: 是 | M26: 否 | N26: 管理费用 | O26: 46154
A27: 黄裕晋 | B27: JG0000978 | C27: 黄裕晋 | D27: 人资行政部 | E27: 男 | F27: 默认 | G27: 安全专员 | H27: 默认 | I27: 2024-10-01 | K27: 13922059143 | L27: 是 | M27: 否 | N27: 管理费用 | O27: 45341
A28: 江淑琴 | B28: JG002693 | C28: 江淑琴 | D28: 人资行政部 | E28: 女 | F28: 默认 | G28: 清洁工 | H28: 默认 | I28: 2025-04-25 | K28: 13620100832 | L28: 是 | M28: 否 | N28: 管理费用-福利费 | O28: 45769
A29: 蓝晓姗 | B29: JG000531 | C29: 蓝晓姗 | F29: 默认 | G29: 采购文员 | H29: 默认 | I29: 2021-12-20 | K29: 15602800785 | L29: 是 | M29: 否 | N29: 管理费用
A30: 李彩霞 | B30: JG000126 | C30: 李彩霞 | F30: 默认 | G30: 后勤主管 | H30: 默认 | I30: 2018-08-21 | K30: 13825523408 | L30: 是 | M30: 否 | N30: 管理费用
A31: 李凤州 | B31: JG002764 | C31: 李凤州 | F31: 默认 | G31: 厨工 | H31: 默认 | I31: 2025-06-19 | K31: 19152615613 | L31: 是 | M31: 否 | N31: 管理费用-福利费
A32: 李嘉炜 | B32: JG002998 | C32: 李嘉炜 | F32: 默认 | G32: 后勤杂工 | H32: 默认 | I32: 2026-01-01 | L32: 是 | M32: 否 | N32: 管理费用
A33: 李少英 | B33: JG000200 | C33: 李少英 | F33: 默认 | G33: 清洁工 | H33: 默认 | I33: 2020-10-19 | K33: 13687415729 | L33: 是 | M33: 否 | N33: 管理费用
A34: 李燕清 | B34: JG000012 | C34: 李燕清 | F34: 默认 | G34: 推广专员 | H34: 默认 | I34: 2015-01-01 | K34: 15015643415 | L34: 是 | M34: 否 | N34: 管理费用
A35: 梁健斌 | B35: JG000101 | C35: 梁健斌 | F35: 默认 | G35: 司机 | H35: 默认 | I35: 2018-06-09 | K35: 13925413261 | L35: 是 | M35: 否 | N35: 管理费用
A36: 梁锦贤 | B36: JG000093 | C36: 梁锦贤 | F36: 默认 | G36: 司机 | H36: 默认 | I36: 2018-01-19 | K36: 18927286787 | L36: 是 | M36: 否 | N36: 管理费用
A37: 梁秋星 | B37: JG001666 | C37: 梁秋星 | D37: 人资行政部 | E37: 女 | F37: 默认 | G37: 厨工 | H37: 默认 | I37: 2024-02-27 | K37: 13653060899 | L37: 是 | M37: 否 | N37: 管理费用-福利费 | O37: 45370
A38: 梁雅芝 | B38: JG000091 | C38: 梁雅芝 | F38: 默认 | G38: 会计 | H38: 默认 | I38: 2017-10-25 | K38: 13927727284 | L38: 是 | M38: 否 | N38: 管理费用
A39: 梁意和 | B39: JG001433 | C39: 梁意和 | F39: 默认 | G39: 厨工 | H39: 默认 | I39: 2023-02-13 | K39: 13539963435 | L39: 是 | M39: 否 | N39: 管理费用-福利费
A40: 林青山 | B40: JG000040 | C40: 林青山 | D40: 人资行政部 | E40: 男 | F40: 默认 | G40: 工会主席 | H40: 默认 | I40: 2019-03-30 | K40: 13535720320 | L40: 是 | M40: 否 | N40: 管理费用 | O40: 38887
...

Sheet 入住明细
A1: 序号 | B1: 工号 | C1: 住宿员工姓名 | D1: 性别 | E1: 部门 | F1: 岗位 | G1: 班组 | H1: 考勤班次 | I1: 入住时间 | J1: 入住房号 | K1: 工号
A2: 1 | B2: JG910018 | C2: 植秀悦 | D2: 男 | E2: 生产部 | F2: 生产B班 | G2: B班 | H2: B班 | I2: 44263 | J2: A217 | K2: =VLOOKUP(C2,花名册!A:B,2) -> JG910018
A3: 2 | B3: JG910017 | C3: 徐金英 | D3: 女 | E3: 生产部 | F3: 生产B班 | G3: B班 | H3: B班 | I3: 44652 | J3: B204 | K3: =VLOOKUP(C3,花名册!A:B,2) -> JG910017
A4: 3 | B4: JG002845 | C4: 彭金忆 | D4: 女 | E4: 生产部 | F4: 生产D班 | G4: D班 | H4: D班 | I4: 45908 | J4: A102 | K4: =VLOOKUP(C4,花名册!A:B,2) -> JG002845
A5: 4 | B5: JG002846 | C5: 宋向强 | D5: 男 | E5: 生产部 | F5: 生产D班 | G5: D班 | H5: D班 | I5: 45908 | J5: A102 | K5: =VLOOKUP(C5,花名册!A:B,2) -> JG002846
A6: 5 | B6: JG002155 | C6: 梁智锋 | D6: 男 | E6: 生产部 | F6: 生产D班 | G6: D班 | H6: D班 | I6: 45615 | J6: A103 | K6: =VLOOKUP(C6,花名册!A:B,2) -> JG002155
A7: 6 | B7: JG910018 | C7: 张梦珠 | D7: 女 | E7: 研发中心 | I7: 45615 | J7: A217 | K7: =VLOOKUP(C7,花名册!A:B,2) -> JG910018
A8: 7 | B8: JG001518 | C8: 陈月霞 | D8: 女 | E8: 生产部 | F8: 生产B班 | G8: B班 | H8: B班 | I8: 46183 | J8: A104 | K8: =VLOOKUP(C8,花名册!A:B,2) -> JG001518
A9: 8 | B9: JG000851 | C9: 黄安才 | D9: 男 | E9: 生产部 | F9: 生产B班 | G9: B班 | H9: B班 | I9: 46183 | J9: A104 | K9: =VLOOKUP(C9,花名册!A:B,2) -> JG000851
A10: 9 | B10: JG001557 | C10: 梁刘媚 | D10: 女 | E10: 生产部 | F10: 生产C班 | G10: C班 | H10: C班 | I10: 45280 | J10: A105 | K10: =VLOOKUP(C10,花名册!A:B,2) -> JG001557
A11: 10 | B11: JG000206 | C11: 梁伟满 | D11: 男 | E11: 生产部 | F11: 生产C班 | G11: C班 | H11: C班 | I11: 45280 | J11: A105 | K11: =VLOOKUP(C11,花名册!A:B,2) -> JG000206
A12: 11 | B12: JG000105 | C12: 李文武 | D12: 男 | E12: 生产部 | F12: 生产A班 | G12: A班 | H12: A班 | I12: 43263 | J12: A106 | K12: =VLOOKUP(C12,花名册!A:B,2) -> JG000105
A13: 12 | B13: JG000104 | C13: 刘胜分 | D13: 女 | E13: 生产部 | F13: 生产A班 | G13: A班 | H13: A班 | I13: 43263 | J13: A106 | K13: =VLOOKUP(C13,花名册!A:B,2) -> JG000104
A14: 13 | B14: JG000102 | C14: 莫恩明 | D14: 男 | E14: 生产部 | F14: 生产A班 | G14: A班 | H14: A班 | I14: 43260 | J14: A107 | K14: =VLOOKUP(C14,花名册!A:B,2) -> JG000102
A15: 14 | B15: JG000103 | C15: 陈群丽 | D15: 女 | E15: 生产部 | F15: 生产A班 | G15: A班 | H15: A班 | I15: 43260 | J15: A107 | K15: =VLOOKUP(C15,花名册!A:B,2) -> JG000103
A16: 15 | B16: JG910016 | C16: 王卫芳 | D16: 女 | E16: 生产部 | F16: 生产J班 | G16: J班 | H16: J班 | I16: 46113 | J16: A203 | K16: =VLOOKUP(C16,花名册!A:B,2) -> JG910016
A17: 16 | B17: JG002725 | C17: 侯昌寿 | D17: 男 | E17: 生产部 | F17: 生产J班 | G17: J班 | H17: J班 | I17: 46113 | J17: A108 | K17: =VLOOKUP(C17,花名册!A:B,2) -> JG002725
A18: 17 | B18: JG910016 | C18: 王泽能 | D18: 男 | E18: 生产部 | F18: 生产C班 | G18: C班 | H18: C班 | I18: 44281 | J18: A203 | K18: =VLOOKUP(C18,花名册!A:B,2) -> JG910016
A19: 18 | B19: JG910018 | C19: 祝李梅 | D19: 女 | E19: 生产部 | F19: 生产C班 | G19: C班 | H19: C班 | I19: 44281 | J19: A217 | K19: =VLOOKUP(C19,花名册!A:B,2) -> JG910018
... A21: 20 | B21: JG001514 | C21: 廖明 | D21: 男 | E21: 生产部 | F21: 生产C班 | G21: C班 | H21: C班 | I21: 45080 | J21: A110 | K21: =VLOOKUP(C21,花名册!A:B,2) -> JG001514
A22: 21 | B22: JG001249 | C22: 冯泽荣 | D22: 男 | E22: 生产部 | F22: 生产B班 | G22: B班 | H22: B班 | J22: A111 | K22: =VLOOKUP(C22,花名册!A:B,2) -> JG001249
A23: 22 | B23: JG001250 | C23: 黄春芹 | D23: 女 | E23: 生产部 | F23: 生产B班 | G23: B班 | H23: B班 | J23: A111 | K23: =VLOOKUP(C23,花名册!A:B,2) -> JG001250
A24: 23 | B24: JG001233 | C24: 盘才天 | D24: 男 | E24: 生产部 | F24: 生产J班 | G24: J班 | H24: J班 | J24: A112 | K24: =VLOOKUP(C24,花名册!A:B,2) -> JG001233
A25: 24 | B25: JG910018 | C25: 赵小燕 | D25: 女 | E25: 生产部 | F25: 生产J班 | G25: J班 | H25: J班 | J25: A217 | K25: =VLOOKUP(C25,花名册!A:B,2) -> JG910018
A26: 25 | B26: JG000048 | C26: 李明武 | D26: 男 | E26: 生产部 | F26: 生产A班 | G26: A班 | H26: A班 | I26: 42072 | J26: A113 | K26: =VLOOKUP(C26,花名册!A:B,2) -> JG000048
A27: 26 | B27: JG000049 | C27: 付群飞 | D27: 女 | E27: 生产部 | F27: 生产A班 | G27: A班 | H27: A班 | I27: 42072 | J27: A113 | K27: =VLOOKUP(C27,花名册!A:B,2) -> JG000049
A28: 27 | B28: JG002641 | C28: 全亮明 | D28: 男 | E28: 人资行政部 | F28: 水电工 | J28: A516 | K28: =VLOOKUP(C28,花名册!A:B,2) -> JG002641
A29: 28 | B29: JG002686 | C29: 全任辉 | D29: 男 | E29: 生产部 | F29: 仓管员 | I29: 45839 | J29: A201 | K29: =VLOOKUP(C29,花名册!A:B,2) -> JG002686
A30: 29 | B30: JG910016 | C30: 王桂芳 | D30: 女 | E30: 生产部 | F30: 仓储科 | I30: 2025.12.13 | J30: A203 | K30: =VLOOKUP(C30,花名册!A:B,2) -> JG910016
A31: 30 | B31: JG002881 | C31: 龙建勇 | D31: 男 | E31: 生产部 | F31: 设备科 | I31: 2025.12.13 | J31: A115 | K31: =VLOOKUP(C31,花名册!A:B,2) -> JG002881
A32: 31 | B32: #N/A | C32: 岑盛大 | D32: 男 | E32: 人资行政部 | I32: 43969 | J32: #N/A | K32: =VLOOKUP(C32,花名册!A:B,2) -> #N/A
A33: 32 | B33: JG002886 | C33: 林青山 | D33: 男 | E33: 人资行政部 | I33: 38887 | J33: A115 | K33: =VLOOKUP(C33,花名册!A:B,2) -> JG002886
A34: 33 | B34: JG002025 | C34: 邰进英 | D34: 女 | E34: 生产部 | F34: 生产C班 | G34: C班 | H34: C班 | I34: 45705 | J34: A118 | K34: =VLOOKUP(C34,花名册!A:B,2) -> JG002025
A35: 34 | B35: JG002061 | C35: 廖华 | D35: 男 | E35: 生产部 | F35: 生产C班 | G35: C班 | H35: C班 | I35: 45705 | J35: A118 | K35: =VLOOKUP(C35,花名册!A:B,2) -> JG002061
A36: 35 | B36: JG002686 | C36: 全任辉 | D36: 男 | E36: 生产部 | F36: 仓管员 | I36: 45839 | J36: A201 | K36: =VLOOKUP(C36,花名册!A:B,2) -> JG002686
A37: 36 | B37: #N/A | J37: #N/A | K37: =VLOOKUP(C37,花名册!A:B,2) -> #N/A
A38: 37 | B38: #N/A | J38: #N/A | K38: =VLOOKUP(C38,花名册!A:B,2) -> #N/A
A39: 38 | B39: #N/A | J39: #N/A | K39: =VLOOKUP(C39,花名册!A:B,2) -> #N/A
A40: 39 | B40: JG002005 | C40: 马源辰 | D40: 男 | E40: 研发部 | F40: 研发工程师 | I40: 46204 | J40: B305 | K40: =VLOOKUP(C40,花名册!A:B,2) -> JG002005
A41: 40 | B41: JG000051 | C41: 李乐斌 | D41: 男 | E41: 研发部 | F41: 研发工程师 | I41: 46204 | J41: A113 | K41: =VLOOKUP(C41,花名册!A:B,2) -> JG000051
...

Sheet 宿舍档案
A1: 宿舍房号 | B1: 容量上限
A2: A101 | B2: 2
A3: A102 | B3: 2
A4: A103 | B4: 2
A5: A104 | B5: 2
A6: A105 | B6: 2
A7: A106 | B7: 2
A8: A107 | B8: 2
A9: A108 | B9: 2
A10: A109 | B10: 2
A11: A110 | B11: 2
A12: A111 | B12: 2
A13: A112 | B13: 2
... A141: B607 | B141: 4

Sheet 考勤班次

Sheet 员工班组
A1: 班组
A2: 默认
A3: C班
A4: F班
A5: A班
A6: E班
A7: B班
A8: D班
A9: J班
A10: K班
A11: H班

Sheet 部门
A1: 部门
A3: 人资行政部
A4: 生产部
A5: 采购部
A6: 董秘办
A7: 审计部
A8: 销售部
A9: 研发部

Sheet 6月 
A1: 2026年6月份员工宿舍电费扣费人员明细表
A2: 序号 | B2: 宿舍房号 | C2: 超用电/度 | D2: 入住人数 | E2: 住宿员工姓名 | F2: 性别 | G2: 部门 | H2: 班组/科 | I2: 入住时间 | J2: 扣费金额/元 | K2: 扣费金额/元 | L2: 离职时间 | M2: 备注
A3: 1 | B3: A101 | C3: 0 | D3: =COUNTA(E3:E4) -> 2 | E3: 植秀悦 | F3: 男 | G3: 生产部 | H3: 生产B班 | I3: 44263 | J3: =C3/D3 -> 0
E4: 徐金英 | F4: 女 | G4: 生产部 | H4: 生产B班 | I4: 44652 | J4: =C3/D3 -> 0
A5: 2 | B5: A102 | C5: 125 | D5: =COUNTA(E5:E6) -> 2 | E5: 彭金忆 | F5: 女 | G5: 生产部 | H5: 生产D班 | I5: 45908 | J5: =C5/D5 -> 62.5 | K5: =TRUNC(J5) -> 62
E6: 宋向强 | F6: 男 | G6: 生产部 | H6: 生产D班 | I6: 45908 | J6: =C5/D5 -> 62.5 | K6: =TRUNC(J6) -> 62
A7: 3 | B7: A103 | C7: 0 | D7: =COUNTA(E7:E8) -> 2 | E7: 梁智锋 | F7: 男 | G7: 生产部 | H7: 生产D班 | I7: 45615 | J7: =C7/D7 -> 0
E8: 张梦珠 | F8: 女 | G8: 研发中心 | H8: / | I8: 45615 | J8: =C7/D7 -> 0
A9: 4 | B9: A104 | C9: 0 | D9: =COUNTA(E9:E10) -> 2 | E9: 陈月霞 | F9: 女 | G9: 生产部 | H9: 生产B班 | I9: 46183 | J9: =C9/D9 -> 0
E10: 黄安才 | F10: 男 | G10: 生产部 | H10: 生产B班 | I10: 46183 | J10: =C9/D9 -> 0
A11: 5 | B11: A105 | C11: 239 | D11: =COUNTA(E11:E12) -> 2 | E11: 梁刘媚 | F11: 女 | G11: 生产部 | H11: 生产C班 | I11: 45280 | J11: =C11/D11 -> 119.5 | K11: =TRUNC(J11) -> 119
E12: 梁伟满 | F12: 男 | G12: 生产部 | H12: 生产C班 | I12: 45280 | J12: =C11/D11 -> 119.5 | K12: =TRUNC(J12) -> 119
A13: 6 | B13: A106 | C13: 33 | D13: =COUNTA(E13:E14) -> 2 | E13: 李文武 | F13: 男 | G13: 生产部 | H13: 生产A班 | I13: 43263 | J13: =C13/D13 -> 16.5 | K13: =TRUNC(J13) -> 16
E14: 刘胜分 | F14: 女 | G14: 生产部 | H14: 生产A班 | I14: 43263 | J14: =C13/D13 -> 16.5 | K14: =TRUNC(J14) -> 16
A15: 7 | B15: A107 | C15: 0 | D15: =COUNTA(E15:E16) -> 2 | E15: 莫恩明 | F15: 男 | G15: 生产部 | H15: 生产A班 | I15: 43260 | J15: =C15/D15 -> 0
E16: 陈群丽 | F16: 女 | G16: 生产部 | H16: 生产A班 | I16: 43260 | J16: =C15/D15 -> 0
A17: 8 | B17: A108 | C17: 0 | D17: =COUNTA(E17:E18) -> 2 | E17: 王卫芳 | F17: 女 | G17: 生产部 | H17: 生产J班 | I17: 46113 | J17: =C17/D17 -> 0
E18: 侯昌寿 | F18: 男 | G18: 生产部 | H18: 生产J班 | I18: 46113 | J18: =C17/D17 -> 0
A19: 9 | B19: A109 | C19: 72 | D19: =COUNTA(E19:E20) -> 2 | E19: 王泽能 | F19: 男 | G19: 生产部 | H19: 生产C班 | I19: 44281 | J19: =C19/D19 -> 36 | K19: =TRUNC(J19) -> 36
E20: 祝李梅 | F20: 女 | G20: 生产部 | H20: 生产C班 | I20: 44281 | J20: =C19/D19 -> 36 | K20: =TRUNC(J20) -> 36
A21: 10 | B21: A110 | C21: 0 | D21: =COUNTA(E21:E22) -> 2 | E21: 李燕芸 | F21: 女 | G21: 生产部 | H21: 生产C班 | I21: 44418 | J21: =C21/D21 -> 0
E22: 廖明 | F22: 男 | G22: 生产部 | H22: 生产C班 | I22: 45080 | J22: =C21/D21 -> 0
A23: 11 | B23: A111 | C23: 0 | D23: =COUNTA(E23:E24) -> 2 | E23: 冯泽荣 | F23: 男 | G23: 生产部 | H23: 生产B班 | J23: =C23/D23 -> 0
E24: 黄春芹 | F24: 女 | G24: 生产部 | H24: 生产B班 | J24: =C23/D23 -> 0
A25: 12 | B25: A112 | C25: 0 | D25: =COUNTA(E25:E26) -> 2 | E25: 盘才天 | F25: 男 | G25: 生产部 | H25: 生产J班 | J25: =C25/D25 -> 0
E26: 赵小燕 | F26: 女 | G26: 生产部 | H26: 生产J班 | J26: =C25/D25 -> 0
A27: 13 | B27: A113 | C27: 0 | D27: =COUNTA(E27:E28) -> 2 | E27: 李明武 | F27: 男 | G27: 生产部 | H27: 生产A班 | I27: 42072 | J27: =C27/D27 -> 0
E28: 付群飞 | F28: 女 | G28: 生产部 | H28: 生产A班 | I28: 42072 | J28: =C27/D27 -> 0
A29: 14 | B29: A114 | C29: 0 | D29: 2 | E29: 全亮明 | F29: 男 | G29: 人资行政部 | H29: 水电工 | J29: =C29/D29 -> 0
E30: 全任辉 | F30: 男 | G30: 生产部 | H30: 仓管员 | I30: 45839 | J30: =C29/D29 -> 0 | M30: A201产生电费计算入全任辉
A31: 15 | B31: A115 | C31: 0 | D31: =COUNTA(E31:E32) -> 2 | E31: 王桂芳 | F31: 女 | G31: 生产部 | H31: 仓储科 | I31: 2025.12.13 | J31: =C31/D31 -> 0
E32: 龙建勇 | F32: 男 | G32: 生产部 | H32: 设备科 | I32: 2025.12.13 | J32: =C31/D31 -> 0
A33: 16 | B33: A116 | C33: 0 | D33: =COUNTA(E33) -> 1 | E33: 岑盛大 | F33: 男 | G33: 人资行政部 | H33: / | I33: 43969 | J33: =C33/D33 -> 0
A34: 17 | B34: A117 | C34: 82 | D34: =COUNTA(E34) -> 1 | E34: 林青山 | F34: 男 | G34: 人资行政部 | H34: / | I34: 38887 | J34: =C34/D34 -> 82 | K34: =TRUNC(J34) -> 82
A35: 18 | B35: A118 | C35: 111 | D35: =COUNTA(E35:E36) -> 2 | E35: 邰进英 | F35: 女 | G35: 生产部 | H35: 生产C班 | I35: 45705 | J35: =C35/D35 -> 55.5 | K35: =TRUNC(J35) -> 55
E36: 廖华 | F36: 男 | G36: 生产部 | H36: 生产C班 | I36: 45705 | J36: =C35/D35 -> 55.5 | K36: =TRUNC(J36) -> 55
A37: 19 | B37: A201 | C37: 84 | D37: =COUNTA(E37:E40) -> 1 | E37: 全任辉 | F37: 男 | G37: 生产部 | H37: 仓管员 | I37: 45839 | K37: 84
A41: 20 | B41: A202 | C41: 0 | D41: =COUNTA(E41:E44) -> 2 | E41: 马源辰 | F41: 男 | G41: 研发部 | H41: 研发工程师 | I41: 46204
E42: 李乐斌 | F42: 男 | G42: 研发部 | H42: 研发工程师 | I42: 46204
A45: 21 | B45: A203 | C45: 0 | D45: =COUNTA(E45:E48) -> 1 | E45: 王斌 | F45: 男 | G45: 研发部 | H45: 研发工程师 | I45: 46204
...

Sheet Sheet3
A1: 部门 | B1: 性别 | C1: 考勤班次 | E1: 班组 | G1: 岗位
C2: 默认 | E2: 默认 | G2: A班包装工
A3: 人资行政部 | B3: 男 | E3: C班 | G3: B班包装工
A4: 生产部 | B4: 女 | E4: F班 | G4: 厨师
A5: 采购部 | E5: A班 | G5: 证券事务代表
A6: 董秘办 | E6: E班 | G6: 主厨
A7: 审计部 | E7: B班 | G7: 保安
A8: 销售部 | E8: D班 | G8: 采购员
A9: 研发部 | E9: J班 | G9: 厨工
E10: K班 | G10: 财务经理
E11: H班 | G11: 总监
G12: 后勤杂工
G13: 行政文员
G14: 采购专员
G15: 后勤助理
G16: 中转仓司机
G17: 司机
G18: 薪酬绩效主管
G19: 总经理
G20: 采购主管
G22: 总账会计
G23: 人事文员
G24: 安全专员
... G141: 研发副主管

Sheet BAK
A1: 员工姓名 | B1: 员工编号 | C1: 主任岗岗位 | D1: 主任岗开始日期 | E1: 移动电话 | F1: 来源于s-HR | G1: HR员工 | H1: 费用归属 | I1: 开户银行 | J1: 银行账号 | K1: 账户名称
A2: 陈晓梅 | B2: 陈晓梅 | C2: 行政人员 | D2: 2022-01-01 | E2: 15815662220 | F2: 否 | G2: 否
A3: 黎思华 | B3: 黎思华 | C3: 业务员 | D3: 2022-01-01 | E3: 13211185890 | F3: 否 | G3: 否
A4: 马俊杰 | B4: 马俊杰 | C4: 行政人员 | D4: 2022-01-01 | E4: 13794038119 | F4: 否 | G4: 否
A5: 潘英彩 | B5: 潘英彩 | C5: 销售员 | D5: 2024-04-18 | E5: 13420643955 | F5: 否 | G5: 否
A6: 审计 | B6: 审计 | E6: 13536600218 | F6: 否 | G6: 否
A7: 夏结仪 | B7: 夏结仪 | C7: 业务员 | D7: 2022-01-01 | E7: 15899575247 | F7: 否 | G7: 否
A8: 杨宗铭 | B8: 杨宗铭 | C8: 业务员 | D8: 2022-04-21 | E8: 13425680418 | F8: 否 | G8: 否
A9: 员工 | B9: 员工 | C9: 业务员 | D9: 2022-11-01 | F9: 否 | G9: 否
A10: 张芳 | B10: 张芳 | C10: 业务员 | D10: 2022-04-21 | E10: 13695298197 | F10: 否 | G10: 否
A11: 郑飞飞 | B11: 郑飞飞 | C11: 采购专员 | D11: 2023-06-15 | E11: 13415781685 | F11: 否 | G11: 否
A12: 1s-HRDEL250515161349 | B12: 1s-HRDEL250515161349 | C12: 董事会秘书 | D12: 2025-05-15 | F12: 是 | G12: 否 | H12: 1
A13: 班玩兰 | B13: JG003049 | C13: C班包装工 | D13: 2026-03-07 | F13: 是 | G13: 否 | H13: 生产部-直接人工
A14: 毕丽平 | B14: JG001731 | C14: K班普工 | D14: 2024-04-24 | E14: 13138526867 | F14: 是 | G14: 否 | H14: 生产部-直接人工
A15: 蔡金星 | B15: JG003233 | C15: 厨师 | D15: 2026-06-25 | F15: 是 | G15: 否 | H15: 管理费用-福利费
A16: 蔡玲燕 | B16: JG000208 | C16: 技术文员 | D16: 2024-11-01 | E16: 15363083356 | F16: 是 | G16: 否 | H16: 研发费用
A17: 蔡文妹 | B17: JG002761 | C17: 仓管员 | D17: 2025-06-20 | E17: 15813644472 | F17: 是 | G17: 否 | H17: 生产部-直接人工
A18: 蔡伊萍 | B18: JG002666 | C18: F班包装工 | D18: 2025-04-11 | E18: 18718984298 | F18: 是 | G18: 否 | H18: 生产部-直接人工
A19: 蔡源琪 | B19: JG002615 | C19: 证券事务代表 | D19: 2025-03-24 | E19: 18824625725 | F19: 是 | G19: 否 | H19: 管理费用
A20: 蔡子健 | B20: JG001834 | C20: 研发工程师 | D20: 2024-06-26 | F20: 是 | G20: 否 | H20: 研发费用
A21: 曹石林 | B21: JG002872 | C21: 机修 | D21: 2025-09-22 | F21: 是 | G21: 否 | H21: 生产部-辅助人工
A22: 岑建英 | B22: JG000783 | C22: C班包装工 | D22: 2022-03-04 | E22: 15177682292 | F22: 是 | G22: 否 | H22: 生产部-直接人工
A23: 岑美珠 | B23: JG001820 | C23: 检测工程师 | D23: 2024-06-18 | E23: 13425284468 | F23: 是 | G23: 否 | H23: 研发费用
A24: 岑盛大 | B24: JG000170 | C24: 主厨 | D24: 2020-05-18 | E24: 13202645700 | F24: 是 | G24: 否 | H24: 管理费用-福利费
A25: 曾炳棣 | B25: JG001636 | C25: 仓管员 | D25: 2023-11-06 | E25: 13570533360 | F25: 是 | G25: 否 | H25: 生产部-辅助人工
A26: 曾红全 | B26: JG000066 | C26: 保安 | D26: 2016-04-23 | E26: 18823097450 | F26: 是 | G26: 否 | H26: 管理费用
A27: 曾健楚 | B27: JG001355 | C27: 业务员 | D27: 2023-02-01 | E27: 13247548834 | F27: 是 | G27: 否 | H27: 销售费用
A28: 曾锦文 | B28: VK000001 | C28: 业务员 | D28: 2012-11-01 | E28: 13528960343 | F28: 是 | G28: 否 | H28: 销售费用
A29: 曾晋 | B29: JG002127 | C29: 质检技术员 | D29: 2024-10-23 | E29: 15790683551 | F29: 是 | G29: 否 | H29: 生产部-辅助人工
A30: 曾令雄 | B30: JG002774 | C30: 高级研发工程师 | D30: 2025-07-03 | E30: 13617342061 | F30: 是 | G30: 否 | H30: 研发费用
A31: 曾伟光 | B31: JG000193 | C31: A班生产助班 | D31: 2020-08-12 | E31: 15915207308 | F31: 是 | G31: 否 | H31: 生产部-直接人工
A32: 曾卫东 | B32: JG002829 | C32: B班包装工 | D32: 2025-08-23 | F32: 是 | G32: 否 | H32: 生产部-直接人工
A33: 曾妍 | B33: JG003184 | C33: H班生产作业员 | D33: 2026-05-27 | F33: 是 | G33: 否 | H33: 生产部-直接人工
A34: 曾昭煜 | B34: JG000789 | C34: C班包装工 | D34: 2022-03-06 | E34: 18307848207 | F34: 是 | G34: 否 | H34: 生产部-直接人工
A35: 曾桢 | B35: JG003227 | C35: H班生产作业员 | D35: 2026-06-23 | F35: 是 | G35: 否 | H35: 生产部-直接人工
A36: 曾梓毅 | B36: JG000594 | C36: 采购员 | D36: 2024-09-03 | E36: 13178538194 | F36: 是 | G36: 否 | H36: 管理费用
A37: 陈宝华 | B37: JG001309 | C37: 跟班机修 | D37: 2022-12-15 | E37: 13535996439 | F37: 是 | G37: 否 | H37: 生产部-辅助人工
A38: 陈必福 | B38: JG001925 | C38: B班包装工 | D38: 2024-08-26 | F38: 是 | G38: 否 | H38: 生产部-直接人工
A39: 陈朝义 | B39: JG001385 | C39: 叉车司机 | D39: 2023-02-06 | E39: 13925424116 | F39: 是 | G39: 否 | H39: 生产部-辅助人工
A40: 陈成 | B40: JG003164 | C40: C班包装工 | D40: 2026-05-12 | F40: 是 | G40: 否 | H40: 生产部-直接人工
...

Sheet Sheet7
A1: 工号 | B1: 住宿员工姓名 | C1: 宿舍房号 | D1: 工号
A2: JG000016 | B2: 郑杰华 | C2: A501 | D2: JG000016
A3: JG000017 | B3: 陈升 | C3: A604 | D3: JG000017
A4: JG000020 | B4: 甘作敬 | C4: A307 | D4: JG000020
A5: JG000021 | B5: 罗贤添 | C5: A307 | D5: JG000021
A6: JG000029 | B6: 吴波 | C6: A616 | D6: JG000029
A7: JG000033 | B7: 全亮明 | C7: A114 | D7: JG000033
A8: JG000034 | B8: 宋秀玲 | C8: B202 | D8: JG000034
A9: JG000040 | B9: 林青山 | C9: A117 | D9: JG000040
A10: JG000042 | B10: 黄木养 | C10: A304 | D10: JG000042
A11: JG000045 | B11: 梁任湘 | C11: A501 | D11: JG000045
A12: JG000046 | B12: 李永超 | C12: B501 | D12: JG000046
... A348: JG910018 | B348: 杨文慧 | C348: A217 | D348: JG910018
